<?xml version="1.0"?>
<robot name="gripper" xmlns:xacro="http://www.ros.org/wiki/xacro">

    <link name="gripper_base_link">
        <visual>
            <origin xyz="0 0 0.01" rpy="0 0 0" />
            <geometry>
                <box size="0.2 0.06 0.02" />
            </geometry>
            <material name="dark_red" />
        </visual>
        <collision>
            <origin xyz="0 0 0.01" rpy="0 0 0" />
            <geometry>
                <box size="0.2 0.06 0.02" />
            </geometry>
        </collision>
    </link>

    <link name="gripper_left_link">
        <visual>
            <origin xyz="0 0 0.04" rpy="0 0 0" />
            <geometry>
                <box size="0.02 0.06 0.08" />
            </geometry>
            <material name="dark_green" />
        </visual>
        <collision>
            <origin xyz="0 0 0.04" rpy="0 0 0" />
            <geometry>
                <box size="0.02 0.06 0.08" />
            </geometry>
        </collision>
    </link>

    <joint name="gripper_left_finger_joint" type="prismatic">
        <parent link="gripper_base_link" />
        <child link="gripper_left_link" />
        <origin xyz="-0.1 0.0 0.02" rpy="0 0 0" />
        <axis xyz="1 0 0" />
        <limit lower="0.0" upper="0.09" effort="1000.0" velocity="1.0" />
    </joint>

    <link name="gripper_right_link">
        <visual>
            <origin xyz="0 0 0.04" rpy="0 0 0" />
            <geometry>
                <box size="0.02 0.06 0.08" />
            </geometry>
            <material name="dark_green" />
        </visual>
        <collision>
            <origin xyz="0 0 0.04" rpy="0 0 0" />
            <geometry>
                <box size="0.02 0.06 0.08" />
            </geometry>
        </collision>
    </link>

    <joint name="gripper_right_finger_joint" type="prismatic">
        <parent link="gripper_base_link" />
        <child link="gripper_right_link" />
        <origin xyz="0.1 0.0 0.02" rpy="0 0 0" />
        <axis xyz="1 0 0" />
        <mimic joint="gripper_left_finger_joint" multiplier="-1.0" />
        <limit lower="-0.09" upper="0.00" effort="1000.0" velocity="1.0" />
    </joint>

</robot>