<?xml version="1.0"?>
<robot xmlns:xacro="http://www.ros.org/wiki/xacro">

    <xacro:property name="base_length" value="1.0" />
    <xacro:property name="base_width" value="0.5" />
    <xacro:property name="base_height" value="0.3" />
    <xacro:property name="wheel_radius" value="0.15" />
    <xacro:property name="wheel_length" value="0.05" />

    <xacro:macro name="box_inertia" params="m x y z o_xyz o_rpy">
        <inertial>
            <mass value="${m}" />
            <origin xyz="${o_xyz}" rpy="${o_rpy}" />
            <inertia ixx="${(m/12) * (y*y + z*z)}" ixy="0" ixz="0"
                iyy="${(m/12) * (x*x + z*z)}" iyz="0"
                izz="${(m/12) * (x*x + y*y)}" />
        </inertial>
    </xacro:macro>

    <xacro:macro name="cylinder_inertia" params="m r l o_xyz o_rpy">
        <inertial>
            <mass value="${m}" />
            <origin xyz="${o_xyz}" rpy="${o_rpy}" />
            <inertia ixx="${(m/12) * (3*r*r + l*l)}" ixy="0" ixz="0"
                iyy="${(m/12) * (3*r*r + l*l)}" iyz="0"
                izz="${(m/2) * (r*r)}" />
        </inertial>
    </xacro:macro>

    <xacro:macro name="sphere_inertia" params="m r o_xyz o_rpy">
        <inertial>
            <mass value="${m}" />
            <origin xyz="${o_xyz}" rpy="${o_rpy}" />
            <inertia ixx="${(2/5) * m * r * r}" ixy="0" ixz="0"
                iyy="${(2/5) * m * r * r}" iyz="0"
                izz="${(2/5) * m * r * r}" />
        </inertial>
    </xacro:macro>
    <link name="base_footprint" />

    <link name="mobile_base_link">
        <visual>
            <geometry>
                <box size="${base_length} ${base_width} ${base_height}" />
            </geometry>
            <origin xyz="0 0 ${base_height / 2.0}" rpy="0 0 0" />
            <material name="yellow" />
        </visual>
        <collision>
            <geometry>
                <box size="${base_length} ${base_width} ${base_height}" />
            </geometry>
            <origin xyz="0 0 ${base_height / 2.0}" rpy="0 0 0" />
        </collision>
        <xacro:box_inertia m="5.0" x="${base_length}" y="${base_width}" z="${base_height}"
            o_xyz="0 0 ${base_height / 2.0}" o_rpy="0 0 0" />
    </link>

    <xacro:macro name="wheel_link" params="prefix">
        <link name="${prefix}_wheel_link">
            <visual>
                <geometry>
                    <cylinder radius="${wheel_radius}" length="${wheel_length}" />
                </geometry>
                <origin xyz="0 0 0" rpy="${pi / 2.0} 0 0" />
                <material name="grey" />
            </visual>
            <collision>
                <geometry>
                    <sphere radius="${wheel_radius}" />
                </geometry>
                <origin xyz="0 0 0" rpy="0 0 0" />
            </collision>
            <xacro:cylinder_inertia m="1.0" r="${wheel_radius}" l="${wheel_length}"
                o_xyz="0 0 0" o_rpy="${pi / 2.0} 0 0" />
        </link>
    </xacro:macro>

    <xacro:wheel_link prefix="rear_right" />
    <xacro:wheel_link prefix="rear_left" />
    <xacro:wheel_link prefix="front_right" />
    <xacro:wheel_link prefix="front_left" />


    <joint name="base_joint" type="fixed">
        <parent link="base_footprint" />
        <child link="mobile_base_link" />
        <origin xyz="0 0 ${wheel_radius}" rpy="0 0 0" />
    </joint>

    <joint name="base_rear_right_wheel_joint" type="continuous">
        <parent link="mobile_base_link" />
        <child link="rear_right_wheel_link" />
        <origin xyz="${-base_length / 4.0} ${-(base_width + wheel_length) / 2.0} 0" rpy="0 0 0" />
        <axis xyz="0 1 0" />
    </joint>

    <joint name="base_rear_left_wheel_joint" type="continuous">
        <parent link="mobile_base_link" />
        <child link="rear_left_wheel_link" />
        <origin xyz="${-base_length / 4.0} ${(base_width + wheel_length) / 2.0} 0" rpy="0 0 0" />
        <axis xyz="0 1 0" />
    </joint>

    <joint name="base_front_right_wheel_joint" type="continuous">
        <parent link="mobile_base_link" />
        <child link="front_right_wheel_link" />
        <origin xyz="${base_length / 4.0} ${-(base_width + wheel_length) / 2.0} 0" rpy="0 0 0" />
        <axis xyz="0 1 0" />
    </joint>

    <joint name="base_front_left_wheel_joint" type="continuous">
        <parent link="mobile_base_link" />
        <child link="front_left_wheel_link" />
        <origin xyz="${base_length / 4.0} ${(base_width + wheel_length) / 2.0} 0" rpy="0 0 0" />
        <axis xyz="0 1 0" />
    </joint>


</robot>